<?xml version="1.0"?>
<robot xmlns:xacro="http://www.ros.org/wiki/xacro" name="right_arm_macro">

  <xacro:macro name="right_arm" params="prefix">

    <!-- Links -->
    <link name="${prefix}right_shd_fex_link">
      <inertial>
        <origin xyz="0.029672 0.017838 -0.030522" rpy="0 0 0"/>
        <mass value="0.845337"/>
        <inertia ixx="3.656740e-04" ixy="3.442580e-06" ixz="1.213984e-06"
                 iyy="4.788480e-04" iyz="-3.975674e-05" izz="5.335770e-04"/>
      </inertial>
      <visual>
        <origin xyz="0.000000 0.000000 0.000000" rpy="0 0 0"/>
        <geometry>
          <mesh filename="package://harper_description/meshes/right_arm/right_shd_fex_link.dae" scale="1 1 1"/>
        </geometry>
        <material name="Elegoo_PAHT_CF"/>
      </visual>
      <collision>
        <origin xyz="0.000000 0.000000 0.000000" rpy="0 0 0"/>
        <geometry>
          <mesh filename="package://harper_description/meshes/right_arm/right_shd_fex_link_collision.stl" scale="0.01 0.01 0.01"/>
        </geometry>
      </collision>
    </link>

    <link name="${prefix}right_shd_ubk_link">
      <inertial>
        <origin xyz="-0.001692 -0.016243 0.000000" rpy="0 0 0"/>
        <mass value="0.058945"/>
        <inertia ixx="2.875281e-05" ixy="-2.049682e-06" ixz="2.910996e-14"
                 iyy="5.333175e-05" iyz="-1.418383e-13" izz="6.087625e-05"/>
      </inertial>
      <visual>
        <origin xyz="-0.127800 0.002450 0.136700" rpy="0 0 0"/>
        <geometry>
          <mesh filename="package://harper_description/meshes/right_arm/right_shd_ubk_link.dae" scale="1 1 1"/>
        </geometry>
        <material name="Elegoo_PAHT_CF"/>
      </visual>
      <collision>
        <origin xyz="-0.127800 0.002450 0.136700" rpy="0 0 0"/>
        <geometry>
          <mesh filename="package://harper_description/meshes/right_arm/right_shd_ubk_link_collision.stl" scale="0.01 0.01 0.01"/>
        </geometry>
      </collision>
    </link>

    <link name="${prefix}right_shd_aad_link">
      <inertial>
        <origin xyz="0.024728 0.000017 0.016416" rpy="0 0 0"/>
        <mass value="0.741690"/>
        <inertia ixx="3.328065e-04" ixy="-1.091855e-07" ixz="-1.199569e-05"
                 iyy="4.046210e-04" iyz="-3.819490e-07" izz="2.206534e-04"/>
      </inertial>
      <visual>
        <origin xyz="-0.098600 0.039250 0.136700" rpy="0 0 0"/>
        <geometry>
          <mesh filename="package://harper_description/meshes/right_arm/right_shd_aad_link.dae" scale="1 1 1"/>
        </geometry>
        <material name="Elegoo_PAHT_CF"/>
      </visual>
      <collision>
        <origin xyz="-0.098600 0.039250 0.136700" rpy="0 0 0"/>
        <geometry>
          <mesh filename="package://harper_description/meshes/right_arm/right_shd_aad_link_collision.stl" scale="0.01 0.01 0.01"/>
        </geometry>
      </collision>
    </link>

    <link name="${prefix}right_shd_rot_link">
      <inertial>
        <origin xyz="0.007529 0.000340 0.024444" rpy="0 0 0"/>
        <mass value="0.452916"/>
        <inertia ixx="1.475868e-04" ixy="1.267812e-06" ixz="1.692751e-05"
                 iyy="2.217139e-04" iyz="-1.345068e-06" izz="2.038726e-04"/>
      </inertial>
      <visual>
        <origin xyz="-0.129550 0.040250 0.083650" rpy="0 0 0"/>
        <geometry>
          <mesh filename="package://harper_description/meshes/right_arm/right_shd_rot_link.dae" scale="1 1 1"/>
        </geometry>
        <material name="Elegoo_PAHT_CF"/>
      </visual>
      <collision>
        <origin xyz="-0.129550 0.040250 0.083650" rpy="0 0 0"/>
        <geometry>
          <mesh filename="package://harper_description/meshes/right_arm/right_shd_rot_link_collision.stl" scale="0.01 0.01 0.01"/>
        </geometry>
      </collision>
    </link>

    <link name="${prefix}right_elb_upp_link">
      <inertial>
        <origin xyz="0.011593 -0.066507 -0.004958" rpy="0 0 0"/>
        <mass value="0.606734"/>
        <inertia ixx="6.245896e-04" ixy="9.154018e-05" ixz="2.191391e-05"
                 iyy="4.114572e-04" iyz="-4.861266e-05" izz="7.845742e-04"/>
      </inertial>
      <visual>
        <origin xyz="0.000000 0.000000 0.000000" rpy="0 0 0"/>
        <geometry>
          <mesh filename="package://harper_description/meshes/right_arm/right_elb_upp_link.dae" scale="1 1 1"/>
        </geometry>
        <material name="Elegoo_PAHT_CF"/>
      </visual>
      <collision>
        <origin xyz="0.000000 0.000000 0.000000" rpy="0 0 0"/>
        <geometry>
          <mesh filename="package://harper_description/meshes/right_arm/right_elb_upp_link_collision.stl" scale="0.01 0.01 0.01"/>
        </geometry>
      </collision>
    </link>

    <link name="${prefix}right_elb_low_link">
      <inertial>
        <origin xyz="-0.035984 -0.005389 -0.017691" rpy="0 0 0"/>
        <mass value="0.267321"/>
        <inertia ixx="3.771207e-04" ixy="-1.346590e-07" ixz="-6.534874e-08"
                 iyy="3.889453e-04" iyz="2.893217e-05" izz="2.533626e-04"/>
      </inertial>
      <visual>
        <origin xyz="-0.036000 0.152500 0.012500" rpy="0 0 0"/>
        <geometry>
          <mesh filename="package://harper_description/meshes/right_arm/right_elb_low_link.dae" scale="1 1 1"/>
        </geometry>
        <material name="Elegoo_PAHT_CF"/>
      </visual>
      <collision>
        <origin xyz="-0.036000 0.152500 0.012500" rpy="0 0 0"/>
        <geometry>
          <mesh filename="package://harper_description/meshes/right_arm/right_elb_low_link_collision.stl" scale="0.01 0.01 0.01"/>
        </geometry>
      </collision>
    </link>

    <link name="${prefix}right_fam_rot_link">
      <inertial>
        <origin xyz="0.208654 0.004552 0.001199" rpy="0 0 0"/>
        <mass value="0.471550"/>
        <inertia ixx="1.704909e-04" ixy="-9.611486e-06" ixz="-2.780799e-06"
                 iyy="1.961067e-04" iyz="2.959332e-06" izz="2.385457e-04"/>
      </inertial>
      <visual>
        <origin xyz="0.000000 0.000000 0.000000" rpy="0 0 0"/>
        <geometry>
          <mesh filename="package://harper_description/meshes/right_arm/right_fam_rot_link.dae" scale="1 1 1"/>
        </geometry>
        <material name="Elegoo_PAHT_CF"/>
      </visual>
      <collision>
        <origin xyz="0.000000 0.000000 0.000000" rpy="0 0 0"/>
        <geometry>
          <mesh filename="package://harper_description/meshes/right_arm/right_fam_rot_link_collision.stl" scale="0.01 0.01 0.01"/>
        </geometry>
      </collision>
    </link>

    <link name="${prefix}right_wrs_upp_link">
      <inertial>
        <origin xyz="-0.000484 0.034075 0.000023" rpy="0 0 0"/>
        <mass value="0.393034"/>
        <inertia ixx="1.399318e-04" ixy="9.992628e-07" ixz="3.059305e-08"
                 iyy="8.085702e-05" iyz="-3.706349e-08" izz="1.515192e-04"/>
      </inertial>
      <visual>
        <origin xyz="-0.151216 0.060400 0.014518" rpy="0 0 0"/>
        <geometry>
          <mesh filename="package://harper_description/meshes/right_arm/right_wrs_upp_link.dae" scale="1 1 1"/>
        </geometry>
        <material name="Steel"/>
      </visual>
      <collision>
        <origin xyz="-0.151216 0.060400 0.014518" rpy="0 0 0"/>
        <geometry>
          <mesh filename="package://harper_description/meshes/right_arm/right_wrs_upp_link_collision.stl" scale="0.01 0.01 0.01"/>
        </geometry>
      </collision>
    </link>

    <link name="${prefix}right_wrs_low_link">
      <inertial>
        <origin xyz="0.018019 -0.000000 0.017829" rpy="0 0 0"/>
        <mass value="0.013952"/>
        <inertia ixx="2.789670e-06" ixy="-2.341877e-17" ixz="-3.202830e-07"
                 iyy="6.858930e-06" iyz="-9.194034e-17" izz="5.819951e-06"/>
      </inertial>
      <visual>
        <origin xyz="-0.099461 0.489218 -0.332563" rpy="0 0 0"/>
        <geometry>
          <mesh filename="package://harper_description/meshes/right_arm/right_wrs_low_link.dae" scale="1 1 1"/>
        </geometry>
        <material name="Elegoo_PAHT_CF"/>
      </visual>
      <collision>
        <origin xyz="-0.099461 0.489218 -0.332563" rpy="0 0 0"/>
        <geometry>
          <mesh filename="package://harper_description/meshes/right_arm/right_wrs_low_link_collision.stl" scale="0.01 0.01 0.01"/>
        </geometry>
      </collision>
    </link>

    <link name="${prefix}right_plm_link">
      <inertial>
        <origin xyz="0.207483 -0.000843 -0.012890" rpy="0 0 0"/>
        <mass value="0.689230"/>
        <inertia ixx="4.023178e-04" ixy="-2.873884e-05" ixz="-1.959317e-05"
                 iyy="2.817400e-04" iyz="1.798472e-05" izz="5.726841e-04"/>
      </inertial>
      <visual>
        <origin xyz="0.000000 0.000000 0.000000" rpy="0 0 0"/>
        <geometry>
          <mesh filename="package://harper_description/meshes/right_arm/right_plm_link.dae" scale="1 1 1"/>
        </geometry>
        <material name="Steel"/>
      </visual>
      <collision>
        <origin xyz="0.000000 0.000000 0.000000" rpy="0 0 0"/>
        <geometry>
          <mesh filename="package://harper_description/meshes/right_arm/right_plm_link_collision.stl" scale="0.01 0.01 0.01"/>
        </geometry>
      </collision>
    </link>

    <link name="${prefix}right_thb_mip_link">
      <inertial>
        <origin xyz="0.000037 -0.003242 -0.014611" rpy="0 0 0"/>
        <mass value="0.014001"/>
        <inertia ixx="1.497834e-06" ixy="-1.184784e-09" ixz="2.914940e-08"
                 iyy="1.699376e-06" iyz="4.807453e-08" izz="1.096217e-06"/>
      </inertial>
      <visual>
        <origin xyz="0.034146 0.021729 0.001708" rpy="0 0 0"/>
        <geometry>
          <mesh filename="package://harper_description/meshes/right_arm/right_thb_mip_link.dae" scale="1 1 1"/>
        </geometry>
        <material name="Elegoo_PAHT_CF"/>
      </visual>
      <collision>
        <origin xyz="0.034146 0.021729 0.001708" rpy="0 0 0"/>
        <geometry>
          <mesh filename="package://harper_description/meshes/right_arm/right_thb_mip_link_collision.stl" scale="0.01 0.01 0.01"/>
        </geometry>
      </collision>
    </link>

    <link name="${prefix}right_ind_mip_link">
      <inertial>
        <origin xyz="-0.000004 -0.004497 -0.019147" rpy="0 0 0"/>
        <mass value="0.014534"/>
        <inertia ixx="2.133054e-06" ixy="1.144574e-08" ixz="3.753588e-08"
                 iyy="1.839188e-06" iyz="6.203136e-08" izz="1.000000e-06"/>
      </inertial>
      <visual>
        <origin xyz="0.006373 0.019054 0.000788" rpy="0 0 0"/>
        <geometry>
          <mesh filename="package://harper_description/meshes/right_arm/right_ind_mip_link.dae" scale="1 1 1"/>
        </geometry>
        <material name="Elegoo_PAHT_CF"/>
      </visual>
      <collision>
        <origin xyz="0.006373 0.019054 0.000788" rpy="0 0 0"/>
        <geometry>
          <mesh filename="package://harper_description/meshes/right_arm/right_ind_mip_link_collision.stl" scale="0.01 0.01 0.01"/>
        </geometry>
      </collision>
    </link>

    <link name="${prefix}right_mid_mip_link">
      <inertial>
        <origin xyz="0.000052 -0.003168 -0.020409" rpy="0 0 0"/>
        <mass value="0.015491"/>
        <inertia ixx="2.557012e-06" ixy="-7.190002e-10" ixz="1.411528e-08"
                 iyy="2.245838e-06" iyz="7.453491e-08" izz="1.030054e-06"/>
      </inertial>
      <visual>
        <origin xyz="-0.016386 0.022165 0.001288" rpy="0 0 0"/>
        <geometry>
          <mesh filename="package://harper_description/meshes/right_arm/right_mid_mip_link.dae" scale="1 1 1"/>
        </geometry>
        <material name="Elegoo_PAHT_CF"/>
      </visual>
      <collision>
        <origin xyz="-0.016386 0.022165 0.001288" rpy="0 0 0"/>
        <geometry>
          <mesh filename="package://harper_description/meshes/right_arm/right_mid_mip_link_collision.stl" scale="0.01 0.01 0.01"/>
        </geometry>
      </collision>
    </link>

    <link name="${prefix}right_rng_mip_link">
      <inertial>
        <origin xyz="-0.000026 -0.004801 -0.019809" rpy="0 0 0"/>
        <mass value="0.012875"/>
        <inertia ixx="1.956035e-06" ixy="-3.402887e-10" ixz="1.846997e-08"
                 iyy="1.744192e-06" iyz="3.631487e-08" izz="1.000000e-06"/>
      </inertial>
      <visual>
        <origin xyz="-0.038882 0.021552 0.000842" rpy="0 0 0"/>
        <geometry>
          <mesh filename="package://harper_description/meshes/right_arm/right_rng_mip_link.dae" scale="1 1 1"/>
        </geometry>
        <material name="Elegoo_PAHT_CF"/>
      </visual>
      <collision>
        <origin xyz="-0.038882 0.021552 0.000842" rpy="0 0 0"/>
        <geometry>
          <mesh filename="package://harper_description/meshes/right_arm/right_rng_mip_link_collision.stl" scale="0.01 0.01 0.01"/>
        </geometry>
      </collision>
    </link>

    <link name="${prefix}right_pnk_mip_link">
      <inertial>
        <origin xyz="0.000182 -0.004832 -0.015541" rpy="0 0 0"/>
        <mass value="0.009396"/>
        <inertia ixx="1.036512e-06" ixy="1.810997e-08" ixz="1.375956e-09"
                 iyy="1.000000e-06" iyz="6.026527e-08" izz="1.000000e-06"/>
      </inertial>
      <visual>
        <origin xyz="-0.060161 0.021654 0.000950" rpy="0 0 0"/>
        <geometry>
          <mesh filename="package://harper_description/meshes/right_arm/right_pnk_mip_link.dae" scale="1 1 1"/>
        </geometry>
        <material name="Elegoo_PAHT_CF"/>
      </visual>
      <collision>
        <origin xyz="-0.060161 0.021654 0.000950" rpy="0 0 0"/>
        <geometry>
          <mesh filename="package://harper_description/meshes/right_arm/right_pnk_mip_link_collision.stl" scale="0.01 0.01 0.01"/>
        </geometry>
      </collision>
    </link>

    <link name="${prefix}right_thb_ip_link">
      <inertial>
        <origin xyz="-0.000149 -0.005315 -0.012016" rpy="0 0 0"/>
        <mass value="0.008473"/>
        <inertia ixx="1.000000e-06" ixy="3.220812e-09" ixz="1.283854e-08"
                 iyy="1.000000e-06" iyz="-7.299486e-08" izz="1.000000e-06"/>
      </inertial>
      <visual>
        <origin xyz="0.032008 -0.033550 0.001229" rpy="0 0 0"/>
        <geometry>
          <mesh filename="package://harper_description/meshes/right_arm/right_thb_ip_link.dae" scale="1 1 1"/>
        </geometry>
        <material name="Elegoo_PAHT_CF"/>
      </visual>
      <collision>
        <origin xyz="0.032008 -0.033550 0.001229" rpy="0 0 0"/>
        <geometry>
          <mesh filename="package://harper_description/meshes/right_arm/right_thb_ip_link_collision.stl" scale="0.01 0.01 0.01"/>
        </geometry>
      </collision>
    </link>

    <link name="${prefix}right_ind_pip_link">
      <inertial>
        <origin xyz="0.000002 -0.003016 0.011825" rpy="0 0 0"/>
        <mass value="0.006319"/>
        <inertia ixx="1.000000e-06" ixy="7.902947e-10" ixz="1.225982e-08"
                 iyy="1.000000e-06" iyz="7.309719e-09" izz="1.000000e-06"/>
      </inertial>
      <visual>
        <origin xyz="0.006045 -0.007487 0.023772" rpy="0 0 0"/>
        <geometry>
          <mesh filename="package://harper_description/meshes/right_arm/right_ind_pip_link.dae" scale="1 1 1"/>
        </geometry>
        <material name="Elegoo_PAHT_CF"/>
      </visual>
      <collision>
        <origin xyz="0.006045 -0.007487 0.023772" rpy="0 0 0"/>
        <geometry>
          <mesh filename="package://harper_description/meshes/right_arm/right_ind_pip_link_collision.stl" scale="0.01 0.01 0.01"/>
        </geometry>
      </collision>
    </link>

    <link name="${prefix}right_mid_pip_link">
      <inertial>
        <origin xyz="-0.000014 -0.004615 -0.011833" rpy="0 0 0"/>
        <mass value="0.007683"/>
        <inertia ixx="1.000000e-06" ixy="7.656627e-10" ixz="1.424454e-08"
                 iyy="1.000000e-06" iyz="7.609046e-09" izz="1.000000e-06"/>
      </inertial>
      <visual>
        <origin xyz="-0.015931 -0.007785 0.001626" rpy="0 0 0"/>
        <geometry>
          <mesh filename="package://harper_description/meshes/right_arm/right_mid_pip_link.dae" scale="1 1 1"/>
        </geometry>
        <material name="Elegoo_PAHT_CF"/>
      </visual>
      <collision>
        <origin xyz="-0.015931 -0.007785 0.001626" rpy="0 0 0"/>
        <geometry>
          <mesh filename="package://harper_description/meshes/right_arm/right_mid_pip_link_collision.stl" scale="0.01 0.01 0.01"/>
        </geometry>
      </collision>
    </link>

    <link name="${prefix}right_rng_pip_link">
      <inertial>
        <origin xyz="0.000001 -0.004646 -0.011014" rpy="0 0 0"/>
        <mass value="0.006684"/>
        <inertia ixx="1.000000e-06" ixy="6.798552e-10" ixz="1.217085e-08"
                 iyy="1.000000e-06" iyz="1.009502e-08" izz="1.000000e-06"/>
      </inertial>
      <visual>
        <origin xyz="-0.038338 -0.008777 0.001651" rpy="0 0 0"/>
        <geometry>
          <mesh filename="package://harper_description/meshes/right_arm/right_rng_pip_link.dae" scale="1 1 1"/>
        </geometry>
        <material name="Elegoo_PAHT_CF"/>
      </visual>
      <collision>
        <origin xyz="-0.038338 -0.008777 0.001651" rpy="0 0 0"/>
        <geometry>
          <mesh filename="package://harper_description/meshes/right_arm/right_rng_pip_link_collision.stl" scale="0.01 0.01 0.01"/>
        </geometry>
      </collision>
    </link>

    <link name="${prefix}right_pnk_pip_link">
      <inertial>
        <origin xyz="-0.000024 -0.004002 -0.008244" rpy="0 0 0"/>
        <mass value="0.003318"/>
        <inertia ixx="1.000000e-06" ixy="5.294559e-10" ixz="5.655726e-09"
                 iyy="1.000000e-06" iyz="2.435105e-09" izz="1.000000e-06"/>
      </inertial>
      <visual>
        <origin xyz="-0.059964 -0.008313 0.001313" rpy="0 0 0"/>
        <geometry>
          <mesh filename="package://harper_description/meshes/right_arm/right_pnk_pip_link.dae" scale="1 1 1"/>
        </geometry>
        <material name="Elegoo_PAHT_CF"/>
      </visual>
      <collision>
        <origin xyz="-0.059964 -0.008313 0.001313" rpy="0 0 0"/>
        <geometry>
          <mesh filename="package://harper_description/meshes/right_arm/right_pnk_pip_link_collision.stl" scale="0.01 0.01 0.01"/>
        </geometry>
      </collision>
    </link>

    <link name="${prefix}right_ind_dip_link">
      <inertial>
        <origin xyz="-0.000148 -0.003330 -0.010529" rpy="0 0 0"/>
        <mass value="0.004569"/>
        <inertia ixx="1.000000e-06" ixy="1.850180e-10" ixz="5.130864e-09"
                 iyy="1.000000e-06" iyz="-1.654558e-08" izz="1.000000e-06"/>
      </inertial>
      <visual>
        <origin xyz="0.005517 -0.032210 0.001229" rpy="0 0 0"/>
        <geometry>
          <mesh filename="package://harper_description/meshes/right_arm/right_ind_dip_link.dae" scale="1 1 1"/>
        </geometry>
        <material name="Elegoo_PAHT_CF"/>
      </visual>
      <collision>
        <origin xyz="0.005517 -0.032210 0.001229" rpy="0 0 0"/>
        <geometry>
          <mesh filename="package://harper_description/meshes/right_arm/right_ind_dip_link_collision.stl" scale="0.01 0.01 0.01"/>
        </geometry>
      </collision>
    </link>

    <link name="${prefix}right_mid_dip_link">
      <inertial>
        <origin xyz="-0.000126 -0.002947 -0.012174" rpy="0 0 0"/>
        <mass value="0.005368"/>
        <inertia ixx="1.000000e-06" ixy="8.181024e-11" ixz="6.128163e-09"
                 iyy="1.000000e-06" iyz="-2.146251e-08" izz="1.000000e-06"/>
      </inertial>
      <visual>
        <origin xyz="-0.015864 -0.031265 0.001095" rpy="0 0 0"/>
        <geometry>
          <mesh filename="package://harper_description/meshes/right_arm/right_mid_dip_link.dae" scale="1 1 1"/>
        </geometry>
        <material name="Elegoo_PAHT_CF"/>
      </visual>
      <collision>
        <origin xyz="-0.015864 -0.031265 0.001095" rpy="0 0 0"/>
        <geometry>
          <mesh filename="package://harper_description/meshes/right_arm/right_mid_dip_link_collision.stl" scale="0.01 0.01 0.01"/>
        </geometry>
      </collision>
    </link>

    <link name="${prefix}right_rng_dip_link">
      <inertial>
        <origin xyz="-0.000145 -0.002984 -0.011449" rpy="0 0 0"/>
        <mass value="0.004682"/>
        <inertia ixx="1.000000e-06" ixy="1.354234e-11" ixz="5.737561e-09"
                 iyy="1.000000e-06" iyz="-1.655248e-08" izz="1.000000e-06"/>
      </inertial>
      <visual>
        <origin xyz="-0.037645 -0.031209 0.001172" rpy="0 0 0"/>
        <geometry>
          <mesh filename="package://harper_description/meshes/right_arm/right_rng_dip_link.dae" scale="1 1 1"/>
        </geometry>
        <material name="Elegoo_PAHT_CF"/>
      </visual>
      <collision>
        <origin xyz="-0.037645 -0.031209 0.001172" rpy="0 0 0"/>
        <geometry>
          <mesh filename="package://harper_description/meshes/right_arm/right_rng_dip_link_collision.stl" scale="0.01 0.01 0.01"/>
        </geometry>
      </collision>
    </link>

    <link name="${prefix}right_pnk_dip_link">
      <inertial>
        <origin xyz="-0.000129 -0.003249 -0.010295" rpy="0 0 0"/>
        <mass value="0.003302"/>
        <inertia ixx="1.000000e-06" ixy="-1.184337e-11" ixz="3.259371e-09"
                 iyy="1.000000e-06" iyz="-1.132691e-08" izz="1.000000e-06"/>
      </inertial>
      <visual>
        <origin xyz="-0.059244 -0.030617 0.001330" rpy="0 0 0"/>
        <geometry>
          <mesh filename="package://harper_description/meshes/right_arm/right_pnk_dip_link.dae" scale="1 1 1"/>
        </geometry>
        <material name="Elegoo_PAHT_CF"/>
      </visual>
      <collision>
        <origin xyz="-0.059244 -0.030617 0.001330" rpy="0 0 0"/>
        <geometry>
          <mesh filename="package://harper_description/meshes/right_arm/right_pnk_dip_link_collision.stl" scale="0.01 0.01 0.01"/>
        </geometry>
      </collision>
    </link>

    <!-- Joints (internal to assembly) -->
    <joint name="${prefix}right_shd_fex_joint" type="revolute">
      <parent link="${prefix}right_shd_fex_link"/>
      <child link="${prefix}right_shd_ubk_link"/>
      <origin xyz="0.044850 -0.009086 -0.040320" rpy="0.261799 0.000000 -0.000000"/>
      <axis xyz="0.000000 -1.000000 -0.000000"/>
      <limit lower="-1.221730" upper="3.490659" effort="100.0" velocity="1.00"/>
    </joint>

    <joint name="${prefix}right_shd_aad_joint" type="revolute">
      <parent link="${prefix}right_shd_ubk_link"/>
      <child link="${prefix}right_shd_aad_link"/>
      <origin xyz="-0.029300 -0.036800 0.000000" rpy="-0.000000 0.000000 0.000000"/>
      <axis xyz="1.000000 -0.000000 0.000000"/>
      <limit lower="-0.261799" upper="3.141593" effort="100.0" velocity="1.00"/>
    </joint>

    <joint name="${prefix}right_shd_rot_joint" type="revolute">
      <parent link="${prefix}right_shd_aad_link"/>
      <child link="${prefix}right_shd_rot_link"/>
      <origin xyz="0.030950 -0.000800 0.054250" rpy="0.000000 0.000000 0.000000"/>
      <axis xyz="0.000000 -0.000000 -1.000000"/>
      <limit lower="-2.356194" upper="2.356194" effort="100.0" velocity="1.00"/>
    </joint>

    <joint name="${prefix}right_shd_elb_rigid" type="fixed">
      <parent link="${prefix}right_shd_rot_link"/>
      <child link="${prefix}right_elb_upp_link"/>
      <origin xyz="-0.000000 0.001000 0.050699" rpy="-1.570796 -0.000000 -1.570796"/>
    </joint>

    <joint name="${prefix}right_elb_fex_joint" type="revolute">
      <parent link="${prefix}right_elb_upp_link"/>
      <child link="${prefix}right_elb_low_link"/>
      <origin xyz="0.036100 -0.152500 -0.012500" rpy="-1.570796 -0.000000 0.000000"/>
      <axis xyz="1.000000 0.000000 -0.000000"/>
      <limit lower="0.000000" upper="2.094395" effort="100.0" velocity="1.00"/>
    </joint>

    <joint name="${prefix}right_elb_fam_rigid" type="fixed">
      <parent link="${prefix}right_elb_low_link"/>
      <child link="${prefix}right_fam_rot_link"/>
      <origin xyz="-0.035950 -0.001977 -0.316413" rpy="-0.000000 -1.570796 0.000000"/>
    </joint>

    <joint name="${prefix}right_fam_rot_joint" type="revolute">
      <parent link="${prefix}right_fam_rot_link"/>
      <child link="${prefix}right_wrs_upp_link"/>
      <origin xyz="0.152800 -0.000000 0.000000" rpy="3.141593 0.000000 -1.570796"/>
      <axis xyz="-0.000000 -1.000000 0.000000"/>
      <limit lower="-2.356194" upper="2.356194" effort="100.0" velocity="1.00"/>
    </joint>

    <joint name="${prefix}right_wrist_fex_joint" type="revolute">
      <parent link="${prefix}right_wrs_upp_link"/>
      <child link="${prefix}right_wrs_low_link"/>
      <origin xyz="-0.019216 0.049400 0.000018" rpy="-1.570796 -0.000000 -0.000000"/>
      <axis xyz="-1.000000 0.000000 -0.000000"/>
      <limit lower="-1.221730" upper="1.570796" effort="100.0" velocity="1.00"/>
    </joint>

    <joint name="${prefix}right_fam_plm_rigid" type="fixed">
      <parent link="${prefix}right_wrs_low_link"/>
      <child link="${prefix}right_plm_link"/>
      <origin xyz="0.224900 0.011500 0.077600" rpy="1.570796 0.000000 3.141593"/>
    </joint>

    <joint name="${prefix}right_thb_mip_joint" type="revolute">
      <parent link="${prefix}right_plm_link"/>
      <child link="${prefix}right_thb_mip_link"/>
      <origin xyz="0.243967 0.018792 0.027144" rpy="-2.361496 -0.819679 -2.511804"/>
      <axis xyz="-1.000000 0.000232 0.000273"/>
      <limit lower="-0.523599" upper="1.308997" effort="100.0" velocity="1.00"/>
    </joint>

    <joint name="${prefix}right_ind_mip_joint" type="revolute">
      <parent link="${prefix}right_plm_link"/>
      <child link="${prefix}right_ind_mip_link"/>
      <origin xyz="0.229952 0.055536 -0.009694" rpy="1.773245 -0.002516 0.010593"/>
      <axis xyz="-1.000000 -0.000000 0.000134"/>
      <limit lower="-0.872665" upper="0.436332" effort="100.0" velocity="1.00"/>
    </joint>

    <joint name="${prefix}right_mid_mip_joint" type="revolute">
      <parent link="${prefix}right_plm_link"/>
      <child link="${prefix}right_mid_mip_link"/>
      <origin xyz="0.208982 0.055211 -0.009960" rpy="1.523639 -0.001952 0.051989"/>
      <axis xyz="-0.999633 -0.015872 -0.021950"/>
      <limit lower="-1.745329" upper="0.000000" effort="100.0" velocity="1.00"/>
    </joint>

    <joint name="${prefix}right_rng_mip_joint" type="revolute">
      <parent link="${prefix}right_plm_link"/>
      <child link="${prefix}right_rng_mip_link"/>
      <origin xyz="0.188946 0.046236 -0.011433" rpy="1.688389 0.037658 0.055020"/>
      <axis xyz="-0.998616 -0.051195 0.012081"/>
      <limit lower="-0.959931" upper="0.523599" effort="100.0" velocity="1.00"/>
    </joint>

    <joint name="${prefix}right_pnk_mip_joint" type="revolute">
      <parent link="${prefix}right_plm_link"/>
      <child link="${prefix}right_pnk_mip_link"/>
      <origin xyz="0.170194 0.037448 -0.007165" rpy="1.742133 0.083598 0.059222"/>
      <axis xyz="-0.997302 -0.072643 0.010557"/>
      <limit lower="-1.047198" upper="0.610865" effort="100.0" velocity="1.00"/>
    </joint>

    <joint name="${prefix}right_thb_ip_joint" type="revolute">
      <parent link="${prefix}right_thb_mip_link"/>
      <child link="${prefix}right_thb_ip_link"/>
      <origin xyz="-0.000004 0.000719 -0.031198" rpy="0.393186 0.000458 -0.000055"/>
      <axis xyz="1.000000 0.000244 0.000407"/>
      <limit lower="-1.047198" upper="0.349066" effort="100.0" velocity="1.00"/>
    </joint>

    <joint name="${prefix}right_ind_pip_joint" type="revolute">
      <parent link="${prefix}right_ind_mip_link"/>
      <child link="${prefix}right_ind_pip_link"/>
      <origin xyz="-0.000468 -0.000492 -0.039826" rpy="2.773604 -0.001095 -2.987152"/>
      <axis xyz="-1.000000 -0.000495 0.000829"/>
      <limit lower="-0.872665" upper="0.523599" effort="100.0" velocity="1.00"/>
    </joint>

    <joint name="${prefix}right_mid_pip_joint" type="revolute">
      <parent link="${prefix}right_mid_mip_link"/>
      <child link="${prefix}right_mid_pip_link"/>
      <origin xyz="-0.000223 0.001894 -0.046542" rpy="0.124374 0.000345 -0.000489"/>
      <axis xyz="-1.000000 -0.000273 0.000220"/>
      <limit lower="-0.959931" upper="0.523599" effort="100.0" velocity="1.00"/>
    </joint>

    <joint name="${prefix}right_rng_pip_joint" type="revolute">
      <parent link="${prefix}right_rng_mip_link"/>
      <child link="${prefix}right_rng_pip_link"/>
      <origin xyz="-0.000093 -0.001829 -0.041993" rpy="0.292693 0.025746 -0.038387"/>
      <axis xyz="1.000000 -0.000000 0.000000"/>
      <limit lower="2.094395" upper="3.316126" effort="100.0" velocity="1.00"/>
    </joint>

    <joint name="${prefix}right_pnk_pip_joint" type="revolute">
      <parent link="${prefix}right_pnk_mip_link"/>
      <child link="${prefix}right_pnk_pip_link"/>
      <origin xyz="0.000889 0.000130 -0.034094" rpy="1.021120 -0.077367 -0.027152"/>
      <axis xyz="-0.999913 0.011060 -0.007127"/>
      <limit lower="-0.698132" upper="0.872665" effort="100.0" velocity="1.00"/>
    </joint>

    <joint name="${prefix}right_ind_dip_joint" type="revolute">
      <parent link="${prefix}right_ind_pip_link"/>
      <child link="${prefix}right_ind_dip_link"/>
      <origin xyz="0.000008 0.000728 0.023636" rpy="-2.713830 0.000962 3.141485"/>
      <axis xyz="1.000000 -0.000497 -0.000831"/>
      <limit lower="-0.785398" upper="0.523599" effort="100.0" velocity="1.00"/>
    </joint>

    <joint name="${prefix}right_mid_dip_joint" type="revolute">
      <parent link="${prefix}right_mid_pip_link"/>
      <child link="${prefix}right_mid_dip_link"/>
      <origin xyz="-0.000017 -0.000877 -0.027046" rpy="1.082281 -0.010429 0.015437"/>
      <axis xyz="0.999832 -0.016197 0.008554"/>
      <limit lower="-0.872665" upper="0.436332" effort="100.0" velocity="1.00"/>
    </joint>

    <joint name="${prefix}right_rng_dip_joint" type="revolute">
      <parent link="${prefix}right_rng_pip_link"/>
      <child link="${prefix}right_rng_dip_link"/>
      <origin xyz="-0.000004 -0.000592 -0.025335" rpy="1.041129 0.000018 0.000011"/>
      <axis xyz="-1.000000 0.000265 0.000482"/>
      <limit lower="-0.523599" upper="0.872665" effort="100.0" velocity="1.00"/>
    </joint>

    <joint name="${prefix}right_pnk_dip_joint" type="revolute">
      <parent link="${prefix}right_pnk_pip_link"/>
      <child link="${prefix}right_pnk_dip_link"/>
      <origin xyz="-0.000004 0.000237 -0.018937" rpy="1.192406 0.014732 -0.022791"/>
      <axis xyz="-0.999632 -0.022709 0.014809"/>
      <limit lower="-0.436332" upper="0.959931" effort="100.0" velocity="1.00"/>
    </joint>

    <!-- ROS 2 control: generated generic system -->
    <ros2_control name="${prefix}right_arm_system" type="system">
      <hardware>
        <plugin>mock_components/GenericSystem</plugin>
        <param name="cmd_topic">sim/right_arm_system/cmd</param>
        <param name="state_topic">sim/right_arm_system/state</param>
      </hardware>

      <joint name="${prefix}right_elb_fex_joint">
        <command_interface name="position"/>
        <command_interface name="velocity"/>
        <state_interface name="position">
          <param name="initial_value">0.0</param>
        </state_interface>
        <state_interface name="velocity"/>
        <state_interface name="effort"/>
      </joint>
      <joint name="${prefix}right_fam_rot_joint">
        <command_interface name="position"/>
        <command_interface name="velocity"/>
        <state_interface name="position">
          <param name="initial_value">0.0</param>
        </state_interface>
        <state_interface name="velocity"/>
        <state_interface name="effort"/>
      </joint>
      <joint name="${prefix}right_ind_dip_joint">
        <command_interface name="position"/>
        <command_interface name="velocity"/>
        <state_interface name="position">
          <param name="initial_value">0.0</param>
        </state_interface>
        <state_interface name="velocity"/>
        <state_interface name="effort"/>
      </joint>
      <joint name="${prefix}right_ind_mip_joint">
        <command_interface name="position"/>
        <command_interface name="velocity"/>
        <state_interface name="position">
          <param name="initial_value">0.0</param>
        </state_interface>
        <state_interface name="velocity"/>
        <state_interface name="effort"/>
      </joint>
      <joint name="${prefix}right_ind_pip_joint">
        <command_interface name="position"/>
        <command_interface name="velocity"/>
        <state_interface name="position">
          <param name="initial_value">0.0</param>
        </state_interface>
        <state_interface name="velocity"/>
        <state_interface name="effort"/>
      </joint>
      <joint name="${prefix}right_mid_dip_joint">
        <command_interface name="position"/>
        <command_interface name="velocity"/>
        <state_interface name="position">
          <param name="initial_value">0.0</param>
        </state_interface>
        <state_interface name="velocity"/>
        <state_interface name="effort"/>
      </joint>
      <joint name="${prefix}right_mid_mip_joint">
        <command_interface name="position"/>
        <command_interface name="velocity"/>
        <state_interface name="position">
          <param name="initial_value">0.0</param>
        </state_interface>
        <state_interface name="velocity"/>
        <state_interface name="effort"/>
      </joint>
      <joint name="${prefix}right_mid_pip_joint">
        <command_interface name="position"/>
        <command_interface name="velocity"/>
        <state_interface name="position">
          <param name="initial_value">0.0</param>
        </state_interface>
        <state_interface name="velocity"/>
        <state_interface name="effort"/>
      </joint>
      <joint name="${prefix}right_pnk_dip_joint">
        <command_interface name="position"/>
        <command_interface name="velocity"/>
        <state_interface name="position">
          <param name="initial_value">0.0</param>
        </state_interface>
        <state_interface name="velocity"/>
        <state_interface name="effort"/>
      </joint>
      <joint name="${prefix}right_pnk_mip_joint">
        <command_interface name="position"/>
        <command_interface name="velocity"/>
        <state_interface name="position">
          <param name="initial_value">0.0</param>
        </state_interface>
        <state_interface name="velocity"/>
        <state_interface name="effort"/>
      </joint>
      <joint name="${prefix}right_pnk_pip_joint">
        <command_interface name="position"/>
        <command_interface name="velocity"/>
        <state_interface name="position">
          <param name="initial_value">0.0</param>
        </state_interface>
        <state_interface name="velocity"/>
        <state_interface name="effort"/>
      </joint>
      <joint name="${prefix}right_rng_dip_joint">
        <command_interface name="position"/>
        <command_interface name="velocity"/>
        <state_interface name="position">
          <param name="initial_value">0.0</param>
        </state_interface>
        <state_interface name="velocity"/>
        <state_interface name="effort"/>
      </joint>
      <joint name="${prefix}right_rng_mip_joint">
        <command_interface name="position"/>
        <command_interface name="velocity"/>
        <state_interface name="position">
          <param name="initial_value">0.0</param>
        </state_interface>
        <state_interface name="velocity"/>
        <state_interface name="effort"/>
      </joint>
      <joint name="${prefix}right_rng_pip_joint">
        <command_interface name="position"/>
        <command_interface name="velocity"/>
        <state_interface name="position">
          <param name="initial_value">0.0</param>
        </state_interface>
        <state_interface name="velocity"/>
        <state_interface name="effort"/>
      </joint>
      <joint name="${prefix}right_shd_aad_joint">
        <command_interface name="position"/>
        <command_interface name="velocity"/>
        <state_interface name="position">
          <param name="initial_value">0.0</param>
        </state_interface>
        <state_interface name="velocity"/>
        <state_interface name="effort"/>
      </joint>
      <joint name="${prefix}right_shd_fex_joint">
        <command_interface name="position"/>
        <command_interface name="velocity"/>
        <state_interface name="position">
          <param name="initial_value">0.0</param>
        </state_interface>
        <state_interface name="velocity"/>
        <state_interface name="effort"/>
      </joint>
      <joint name="${prefix}right_shd_rot_joint">
        <command_interface name="position"/>
        <command_interface name="velocity"/>
        <state_interface name="position">
          <param name="initial_value">0.0</param>
        </state_interface>
        <state_interface name="velocity"/>
        <state_interface name="effort"/>
      </joint>
      <joint name="${prefix}right_thb_ip_joint">
        <command_interface name="position"/>
        <command_interface name="velocity"/>
        <state_interface name="position">
          <param name="initial_value">0.0</param>
        </state_interface>
        <state_interface name="velocity"/>
        <state_interface name="effort"/>
      </joint>
      <joint name="${prefix}right_thb_mip_joint">
        <command_interface name="position"/>
        <command_interface name="velocity"/>
        <state_interface name="position">
          <param name="initial_value">0.0</param>
        </state_interface>
        <state_interface name="velocity"/>
        <state_interface name="effort"/>
      </joint>
      <joint name="${prefix}right_wrist_fex_joint">
        <command_interface name="position"/>
        <command_interface name="velocity"/>
        <state_interface name="position">
          <param name="initial_value">0.0</param>
        </state_interface>
        <state_interface name="velocity"/>
        <state_interface name="effort"/>
      </joint>
    </ros2_control>

  </xacro:macro>

</robot>